I'm sorry, but an uncaught exception occurred.

While running game code:
  File "game/tl/german/screens.rpy", line 339, in script
    old "Sustainopolis"
Exception: A translation for "Sustainopolis" already exists at game/tl/german/options.rpy:7.

-- Full Traceback ------------------------------------------------------------

Full traceback:
  File "game/tl/german/screens.rpy", line 339, in script
    old "Sustainopolis"
  File "/Applications/renpy-8.3.3-sdk/renpy/ast.py", line 2646, in execute
    renpy.translation.add_string_translation(self.language, self.old, self.new, newloc)
  File "/Applications/renpy-8.3.3-sdk/renpy/translation/__init__.py", line 594, in add_string_translation
    stl.add(old, new, newloc)
  File "/Applications/renpy-8.3.3-sdk/renpy/translation/__init__.py", line 534, in add
    raise Exception("A translation for \"{}\" already exists at {}:{}.".format(
Exception: A translation for "Sustainopolis" already exists at game/tl/german/options.rpy:7.

macOS-10.16-x86_64-i386-64bit x86_64
Ren'Py 8.3.3.24111502
Sustainopolis 1.0
Mon Dec  9 15:52:53 2024
